Branch 'gh-pages' set up to track remote branch 'gh-pages' from 'origin'.
Previous HEAD position was 30f235e... ENA has been taking some time to come back of late
Switched to branch 'gh-pages'
Your branch is up to date with 'origin/gh-pages'.
Processing server https://refget.herokuapp.com/
test_info_implement
test_metadata_implement
test_sequence_implement
test_info_implement_default
test_info_circular
test_info_algorithms
test_info_subsequence
test_info_api_version
test_metadata_query_circular_sequence
test_sequence_circular
test_sequence_circular_support_false_errors
test_sequence_circular_support_true_errors
test_metadata_query_by_trunc512
test_metadata_trunc512
test_sequence_query_by_trunc512
test_metadata_implement_default
test_metadata_md5
test_metadata_length
test_metadata_aliases
test_metadata_invalid_checksum_404_error
test_metadata_invalid_encoding_406_error
test_sequence_implement_default
test_sequence_start_end
test_sequence_range
test_sequence_invalid_checksum_404_error
test_sequence_invalid_encoding_406_error
test_sequence_start_end_success_cases
test_sequence_start_end_errors
test_sequence_range_success_cases
test_sequence_range_errors
Processing server https://www.ebi.ac.uk/ena/cram/
test_info_implement
test_metadata_implement
test_sequence_implement
test_info_implement_default
test_info_circular
test_info_algorithms
test_info_subsequence
test_info_api_version
test_metadata_query_circular_sequence
test_sequence_circular
test_sequence_circular_support_false_errors
test_sequence_circular_support_true_errors
test_metadata_query_by_trunc512
test_metadata_trunc512
test_sequence_query_by_trunc512
test_metadata_implement_default
Traceback (most recent call last):
  File "/home/travis/virtualenv/python3.6.3/lib/python3.6/site-packages/urllib3/connectionpool.py", line 600, in urlopen
    chunked=chunked)
  File "/home/travis/virtualenv/python3.6.3/lib/python3.6/site-packages/urllib3/connectionpool.py", line 384, in _make_request
    six.raise_from(e, None)
  File "<string>", line 2, in raise_from
  File "/home/travis/virtualenv/python3.6.3/lib/python3.6/site-packages/urllib3/connectionpool.py", line 380, in _make_request
    httplib_response = conn.getresponse()
  File "/opt/python/3.6.3/lib/python3.6/http/client.py", line 1331, in getresponse
    response.begin()
  File "/opt/python/3.6.3/lib/python3.6/http/client.py", line 297, in begin
    version, status, reason = self._read_status()
  File "/opt/python/3.6.3/lib/python3.6/http/client.py", line 266, in _read_status
    raise RemoteDisconnected("Remote end closed connection without"
http.client.RemoteDisconnected: Remote end closed connection without response

During handling of the above exception, another exception occurred:

Traceback (most recent call last):
  File "/home/travis/virtualenv/python3.6.3/lib/python3.6/site-packages/requests/adapters.py", line 449, in send
    timeout=timeout
  File "/home/travis/virtualenv/python3.6.3/lib/python3.6/site-packages/urllib3/connectionpool.py", line 638, in urlopen
    _stacktrace=sys.exc_info()[2])
  File "/home/travis/virtualenv/python3.6.3/lib/python3.6/site-packages/urllib3/util/retry.py", line 368, in increment
    raise six.reraise(type(error), error, _stacktrace)
  File "/home/travis/virtualenv/python3.6.3/lib/python3.6/site-packages/urllib3/packages/six.py", line 685, in reraise
    raise value.with_traceback(tb)
  File "/home/travis/virtualenv/python3.6.3/lib/python3.6/site-packages/urllib3/connectionpool.py", line 600, in urlopen
    chunked=chunked)
  File "/home/travis/virtualenv/python3.6.3/lib/python3.6/site-packages/urllib3/connectionpool.py", line 384, in _make_request
    six.raise_from(e, None)
  File "<string>", line 2, in raise_from
  File "/home/travis/virtualenv/python3.6.3/lib/python3.6/site-packages/urllib3/connectionpool.py", line 380, in _make_request
    httplib_response = conn.getresponse()
  File "/opt/python/3.6.3/lib/python3.6/http/client.py", line 1331, in getresponse
    response.begin()
  File "/opt/python/3.6.3/lib/python3.6/http/client.py", line 297, in begin
    version, status, reason = self._read_status()
  File "/opt/python/3.6.3/lib/python3.6/http/client.py", line 266, in _read_status
    raise RemoteDisconnected("Remote end closed connection without"
urllib3.exceptions.ProtocolError: ('Connection aborted.', RemoteDisconnected('Remote end closed connection without response',))

During handling of the above exception, another exception occurred:

Traceback (most recent call last):
  File "/home/travis/virtualenv/python3.6.3/bin/refget-compliance", line 11, in <module>
    sys.exit(main())
  File "/home/travis/virtualenv/python3.6.3/lib/python3.6/site-packages/click/core.py", line 764, in __call__
    return self.main(*args, **kwargs)
  File "/home/travis/virtualenv/python3.6.3/lib/python3.6/site-packages/click/core.py", line 717, in main
    rv = self.invoke(ctx)
  File "/home/travis/virtualenv/python3.6.3/lib/python3.6/site-packages/click/core.py", line 1137, in invoke
    return _process_result(sub_ctx.command.invoke(sub_ctx))
  File "/home/travis/virtualenv/python3.6.3/lib/python3.6/site-packages/click/core.py", line 956, in invoke
    return ctx.invoke(self.callback, **ctx.params)
  File "/home/travis/virtualenv/python3.6.3/lib/python3.6/site-packages/click/core.py", line 555, in invoke
    return callback(*args, **kwargs)
  File "/home/travis/virtualenv/python3.6.3/lib/python3.6/site-packages/compliance_suite/cli.py", line 87, in report
    tr.run_tests()
  File "/home/travis/virtualenv/python3.6.3/lib/python3.6/site-packages/compliance_suite/test_runner.py", line 133, in run_tests
    self.recurse_run_tests(self.root)
  File "/home/travis/virtualenv/python3.6.3/lib/python3.6/site-packages/compliance_suite/test_runner.py", line 106, in recurse_run_tests
    self.recurse_run_tests(child)
  File "/home/travis/virtualenv/python3.6.3/lib/python3.6/site-packages/compliance_suite/test_runner.py", line 103, in recurse_run_tests
    child.run(self)
  File "/home/travis/virtualenv/python3.6.3/lib/python3.6/site-packages/compliance_suite/tests.py", line 106, in run
    self.algorithm(self, test_runner)
  File "/home/travis/virtualenv/python3.6.3/lib/python3.6/site-packages/compliance_suite/metadata_algorithms.py", line 32, in metadata_implement_default
    response = requests.get(base_url + 'sequence/' + SEQ_MD5)
  File "/home/travis/virtualenv/python3.6.3/lib/python3.6/site-packages/requests/api.py", line 75, in get
    return request('get', url, params=params, **kwargs)
  File "/home/travis/virtualenv/python3.6.3/lib/python3.6/site-packages/requests/api.py", line 60, in request
    return session.request(method=method, url=url, **kwargs)
  File "/home/travis/virtualenv/python3.6.3/lib/python3.6/site-packages/requests/sessions.py", line 533, in request
    resp = self.send(prep, **send_kwargs)
  File "/home/travis/virtualenv/python3.6.3/lib/python3.6/site-packages/requests/sessions.py", line 646, in send
    r = adapter.send(request, **kwargs)
  File "/home/travis/virtualenv/python3.6.3/lib/python3.6/site-packages/requests/adapters.py", line 498, in send
    raise ConnectionError(err, request=request)
requests.exceptions.ConnectionError: ('Connection aborted.', RemoteDisconnected('Remote end closed connection without response',))
